Workbook

Sheet Summary - MH
A1: KIE Benchmark Estimate
A2: Honoapiilani Highway Improvements | 02.09.2026
A4: Discipline | B4: Account Codes | C4: Quantity Description | D4: Key Quantities | E4: Unit | F4: Benchmark MH | G4: Benchmark MH (Custom) | H4: Bottoms Up MH | I4: Notes | J4: Benchmark Production | K4: Benchmark Production (Custom) | L4: Bottoms Up Production
A5: Digital Engineering | B5: 88.40.26 | C5: Anticipated Contract Amount | D5: 300000 | E5: K$ | F5: =DIG_DEL!K9 -> 6643 | G5: =DIG_DEL!K9 -> 6643 | I5: Assumed medium complexity, 24 months base design duration | J5: =IF(D5=0,"",F5/D5) -> 0.022143333 | K5: =IF(D5=0,"",G5/D5) -> 0.022143333 | L5: =IF(D5=0,"",H5/D5) -> 0
A6: Drainage | B6: 88.40.27 | C6: Project Area | D6: 121.5 | E6: AC | F6: =DRN!B22 -> 18013.639 | G6: =DRN!B23 -> 14250.587 | I6: Custom: SEC 820, I-15, I-17, US 97, 264th | J6: =IF(D6=0,"",F6/D6) -> 148.26041 | K6: =IF(D6=0,"",G6/D6) -> 117.28878 | L6: =IF(D6=0,"",H6/D6) -> 0
A7: Environmental | B7: 88.40.39 | C7: Permit Count | D7: 12 | E7: EA | F7: =D7*350 -> 4200 | G7: =D7*350 -> 4200 | I7: Benchmark uses SEC 820 production of 350 MH/EA | J7: =IF(D7=0,"",F7/D7) -> 350 | K7: =IF(D7=0,"",G7/D7) -> 350 | L7: =IF(D7=0,"",H7/D7) -> 0
A8: MOT | B8: 88.40.37 | C8: Roadway Alignment Length | D8: 34910 | E8: LF | F8: =MOT!B22 -> 10529.532 | G8: =MOT!B23 -> 8563.4357 | I8: Custom: SEC 820, I-15, I-17, US 97, 264th | J8: =IF(D8=0,"",F8/D8) -> 0.30161938 | K8: =IF(D8=0,"",G8/D8) -> 0.24530036 | L8: =IF(D8=0,"",H8/D8) -> 0
A9: Roadway (Civil) | B9: 88.40.47, 88.40.39 | C9: Roadway Alignment Length | D9: 34910 | E9: LF | F9: =RDWY!B25 -> 15829.044 | G9: =RDWY!B26 -> 20396.745 | I9: Custom: SEC 820, I-15, I-17, US 97, 264th, 30 Crossing | J9: =IF(D9=0,"",F9/D9) -> 0.45342434 | K9: =IF(D9=0,"",G9/D9) -> 0.58426654 | L9: =IF(D9=0,"",H9/D9) -> 0
A10: Traffic | B10: 88.40.65 | C10: Roadway Alignment Length | D10: 34910 | E10: LF | F10: =TRF!B20 -> 9673.1929 | G10: =TRF!B21 -> 7882.0406 | I10: Custom: SEC 820, I-15, I-17, US 97, 264th, 30 Crossing | J10: =IF(D10=0,"",F10/D10) -> 0.27708946 | K10: =IF(D10=0,"",G10/D10) -> 0.22578174 | L10: =IF(D10=0,"",H10/D10) -> 0
A11: Utilities | B11: 88.40.67 | C11: Self-Perform Design Relocations | D11: 15 | E11: EA | F11: =UTL!B16 -> 3802.7994 | G11: =UTL!B17 -> 3719.6299 | I11: Custom: SEC 820, I-15, US 97, 264th | J11: =IF(D11=0,"",F11/D11) -> 253.51996 | K11: =IF(D11=0,"",G11/D11) -> 247.97533 | L11: =IF(D11=0,"",H11/D11) -> 0
A12: Walls (Total) | B12: 88.40.69 | C12: Wall Area | D12: =D13+D14 -> 10310 | E12: SF | F12: =SUBTOTAL(9,F13:F14) -> 433.05381 | G12: =SUBTOTAL(9,G13:G14) -> 473.40342 | I12: Custom: SEC 820, I-15, 30 Crossing, US 97 - All retaining walls, no sound walls | J12: =IF(D12=0,"",F12/D12) -> 0.042003279 | K12: =IF(D12=0,"",G12/D12) -> 0.045916918
A13: Retaining Walls | B13: 88.40.69 (includes Roadway and Structures, excludes Geotech) | C13: Retaining Wall Area | D13: 10310 | E13: SF | F13: =RWAL!B17 -> 433.05381 | G13: =RWAL!B18 -> 473.40342 | I13: Custom: SEC 820, I-15, 30 Crossing, US 97 | J13: =IF(D13=0,"",F13/D13) -> 0.042003279 | K13: =IF(D13=0,"",G13/D13) -> 0.045916918 | L13: =IF(D13=0,"",H13/D13) -> 0
A14: Noise Walls | B14: 88.40.69 (includes Roadway and Structures, excludes Geotech) | C14: Noise Wall Area | E14: SF | F14: =D14*NWAL!E5 -> 0 | G14: =D14*NWAL!E5 -> 0 | I14: Benchmark: SEC 820 | J14: =IF(D14=0,"",F14/D14) | K14: =IF(D14=0,"",G14/D14) | L14: =IF(D14=0,"",H14/D14)
A15: Bridges (Total) | B15: 88.45.81 (excludes MSTR) | C15: Bridge Deck Area | D15: =SUBTOTAL(9,D16:D17) -> 226140 | E15: SF | F15: =SUBTOTAL(9,F16:F17) -> 21240.221 | G15: =SUBTOTAL(9,G16:G17) -> 21240.221 | I15: All PC Girder - Benchmark based on I-15, I-17, SEC 820, US 97 PC bridges | J15: =IF(D15=0,"",F15/D15) -> 0.093925095 | K15: =IF(D15=0,"",G15/D15) -> 0.093925095 | L15: =IF(D15=0,"",H15/D15) -> 0
A16: Bridges (Vehicle - PC Girder - Single Span) | B16: 88.45.81 (excludes MSTR) | C16: Bridge Deck Area | D16: =SUM(STR!D86:D92) -> 50390 | E16: SF | F16: =SUM(STR!C86:C92) -> 16524.296 | G16: =F16 -> 16524.296 | I16: Benchmark based on I-15, I-17, SEC 820, US 97 PC single span bridges | J16: =IF(D16=0,"",F16/D16) -> 0.32792808 | K16: =IF(D16=0,"",G16/D16) -> 0.32792808 | L16: =IF(D16=0,"",H16/D16) -> 0
A17: Bridges (Vehicle - PC Girder - Multi Span) | B17: 88.45.81 (excludes MSTR) | C17: Bridge Deck Area | D17: =STR!D93 -> 175750 | E17: SF | F17: =STR!C93 -> 4715.925 | G17: =F17 -> 4715.925 | I17: Benchmark based on I-15, I-17, SEC 820, PC multi span bridges | J17: =IF(D17=0,"",F17/D17) -> 0.026833144 | K17: =IF(D17=0,"",G17/D17) -> 0.026833144 | L17: =IF(D17=0,"",H17/D17) -> 0
A18: Misc Structures | B18: 88.45.81.036 | C18: RDWY, DRA and TRF MHR | D18: =SUM(G9,G6,G10) -> 42529.373 | E18: MHR | F18: =MSRT!B18 -> 2726.7831 | G18: =MSRT!B19 -> 2032.8413 | I18: Custom: SEC 820, I-15, I-17, 264th | J18: =IF(D18=0,"",F18/D18) -> 0.064115291 | K18: =IF(D18=0,"",G18/D18) -> 0.047798526 | L18: =IF(D18=0,"",H18/D18) -> 0
A19: Geotechnical | B19: 88.50 (includes Retaining Walls) | C19: Transportation Structure Count | D19: 12 | E19: EA | F19: =GEO!$B$22 -> 5787.0806 | G19: =GEO!$B$23 -> 2492.4014 | I19: Custom: SEC 820, I-15, I-17, US 97 | J19: =IF(D19=0,"",F19/D19) -> 482.25672 | K19: =IF(D19=0,"",G19/D19) -> 207.70012 | L19: =IF(D19=0,"",H19/D19) -> 0
A20: Systems | B20: 88.35 | C20: Track Alignment Length | D20: 0 | E20: TF | F20: =SYS!B16 -> 0 | G20: =SYS!B17 -> 0 | I20: No track work anticipated in SOW | J20: =IF(D20=0,"",F20/D20) | K20: =IF(D20=0,"",G20/D20) | L20: =IF(D20=0,"",H20/D20)
A21: Track | B21: 88.40.63 | C21: Track Alignment Length | D21: 0 | E21: TF | F21: =TRK!B16 -> 0 | G21: =TRK!B17 -> 0 | I21: No systems work anticipated in SOW | J21: =IF(D21=0,"",F21/D21) | K21: =IF(D21=0,"",G21/D21) | L21: =IF(D21=0,"",H21/D21)
A22: [OTHER DISCIPLINE] | I22: Non-Benchmarked Discipline | J22: =IF(D22=0,"",F22/D22) | K22: =IF(D22=0,"",G22/D22) | L22: =IF(D22=0,"",H22/D22)
A23: [OTHER DISCIPLINE] | I23: Non-Benchmarked Discipline | J23: =IF(D23=0,"",F23/D23) | K23: =IF(D23=0,"",G23/D23) | L23: =IF(D23=0,"",H23/D23)
A24: ESDC | C24: Anticipated Project Cost | D24: =D5/(1+0.15) -> 260869.57 | E24: K$ | F24: =(ESDC!B54/Dropdowns!B8)/Dropdowns!B9*1000 -> 12483.256 | G24: =(ESDC!B55/Dropdowns!B8)/Dropdowns!B9*1000 -> 13493.46 | J24: =IF(D24=0,"",F24/D24) -> 0.047852483 | K24: =IF(D24=0,"",G24/D24) -> 0.051724931 | L24: =IF(D24=0,"",H24/D24) -> 0
A25: TSCD | C25: Anticipated Project Cost | D25: =D5/(1+0.15) -> 260869.57 | E25: K$ | F25: =(TSCD!B120/Dropdowns!B8)/Dropdowns!B9*1000 -> 4068.3218 | G25: =(TSCD!B121/Dropdowns!B8)/Dropdowns!B9*1000 -> 4619.8317 | J25: =IF(D25=0,"",F25/D25) -> 0.015595233 | K25: =IF(D25=0,"",G25/D25) -> 0.017709355 | L25: =IF(D25=0,"",H25/D25) -> 0
C27: Totals | F27: =SUBTOTAL(9,F5:F25) -> 115429.92 | G27: =SUBTOTAL(9,G5:G25) -> 110007.6 | H27: =SUBTOTAL(9,H5:H25) -> 0

Sheet DIG_DEL
A1: Digital Engineering
A2: eQTY: Anticipated Contract Amount
A4: Design Management - Project Risk Assessment | I4: User Inputs
A5: Size | C5: Complexity | I5: Job Size (Total Job Value) | K5: ='Summary - MH'!D5*1000 -> 300000000
A6: Value | B6: Score | C6: Low | D6: Low-Med | E6: Med | F6: Med-High | G6: High | I6: Complexity Group | K6: Med
A7: <$100M | B7: 1 | C7: 1 | D7: 2 | E7: 4 | F7: 8 | G7: 16 | I7: Complexity Score | K7: 12
A8: $100M - $200M | B8: 2 | C8: 2 | D8: 4 | E8: 8 | F8: 16 | G8: 32 | I8: Design Duration (Months) | K8: 30
A9: $200M - $400M | B9: 3 | C9: 3 | D9: 6 | E9: 12 | F9: 24 | G9: 48 | I9: Digital Delivery - Design Fee Manhours | K9: 6643
A10: $400M - $700M | B10: 6 | C10: 6 | D10: 12 | E10: 24 | F10: 48 | G10: 96
A11: $700M - $1B | B11: 10 | C11: 10 | D11: 20 | E11: 40 | F11: 80 | G11: 160
A12: >$1B | B12: 12 | C12: 12 | D12: 24 | E12: 48 | F12: 96 | G12: 192 | I12: WBS | J12: Description | K12: % of Estimate MH | L12: Benchmark MH
I13: 1.1.4 | J13: Digital Delivery | K13: - | L13: -
A14: Digital Delivery - Project Staffing Plan | I14: 1.1.4.1 | J14: Production Management | K14: 0.22 | L14: =$K$9*K14 -> 1461.46
A15: PRA Score | B15: 1 | C15: 2 | D15: 3 to 6 | E15: 7 to 12 | F15: 13 to 48 | G15: >48 | I15: 1.1.4.2 | J15: Lead Responsibilities / BIM Mgmt | K15: 0.25 | L15: =$K$9*K15 -> 1660.75
A16: Digital Delivery Staff | B16: 0.25 | C16: 0.5 | D16: 1 | E16: 1.5 | F16: 1.6 | G16: 1.75 | I16: 1.1.4.3 | J16: Existing Conditions & Survey | K16: 0.33 | L16: =$K$9*K16 -> 2192.19
A17: Digital Delivery Sponsor | B17: - | C17: - | D17: - | E17: 0.1 | F17: 0.15 | G17: 0.25 | I17: 1.1.4.4 | J17: CAD Management | K17: 0.2 | L17: =$K$9*K17 -> 1328.6
I18: 1.1.4.5 | J18: BIM / CIM / VDC (Unique Client Rqmts) | K18: - | L18: -
A19: Design Duration (Months) | B19: Digital Delivery - Design Fee Manhours
A20: 6 | B20: 260 | C20: 519 | D20: 1308 | E20: 1661 | F20: 1817 | G20: 2076
A21: 7 | B21: 303 | C21: 606 | D21: 1211 | E21: 1938 | F21: 2119 | G21: 2422
A22: 8 | B22: 348 | C22: 692 | D22: 1384 | E22: 2214 | F22: 2422 | G22: 2768
A23: 9 | B23: 389 | C23: 779 | D23: 1557 | E23: 2491 | F23: 2725 | G23: 3114
A24: 10 | B24: 433 | C24: 865 | D24: 1730 | E24: 2768 | F24: 3028 | G24: 3460 | J24: Start Date | K24: 46253
A25: 11 | B25: 476 | C25: 952 | D25: 1903 | E25: 3045 | F25: 3330 | G25: 3806 | J25: End Date | K25: 47175
A26: 12 | B26: 519 | C26: 1038 | D26: 2076 | E26: 3322 | F26: 3633 | G26: 4152 | K26: =K25-K24 -> 922 | L26: days
A27: 13 | B27: 562 | C27: 1125 | D27: 2249 | E27: 3598 | F27: 3936 | G27: 4498 | K27: =K26/7 -> 131.71429 | L27: weeks
A28: 14 | B28: 606 | C28: 1211 | D28: 2422 | E28: 3875 | F28: 4239 | G28: 4844 | K28: =K27/4.33 -> 30.419004 | L28: monhts
A29: 15 | B29: 649 | C29: 1298 | D29: 2595 | E29: 4152 | F29: 4541 | G29: 5190
A30: 16 | B30: 692 | C30: 1384 | D30: 2768 | E30: 4429 | F30: 4844 | G30: 5536
A31: 17 | B31: 735 | C31: 1471 | D31: 2941 | E31: 4706 | F31: 5147 | G31: 5882
A32: 18 | B32: 779 | C32: 1557 | D32: 3114 | E32: 4982 | F32: 5450 | G32: 6228
A33: 19 | B33: 822 | C33: 1644 | D33: 3287 | E33: 5259 | F33: 5752 | G33: 6574
A34: 20 | B34: 865 | C34: 1730 | D34: 3460 | E34: 5536 | F34: 6055 | G34: 6920
A35: 21 | B35: 908 | C35: 1817 | D35: 3633 | E35: 5813 | F35: 6358 | G35: 7266
A36: 22 | B36: 952 | C36: 1903 | D36: 3806 | E36: 6090 | F36: 6661 | G36: 7612
A37: 23 | B37: 995 | C37: 1990 | D37: 3979 | E37: 6366 | F37: 6963 | G37: 7958
A38: 24 | B38: 1038 | C38: 2076 | D38: 4152 | E38: 6643 | F38: 7266 | G38: 8304

Sheet DRN
A1: Drainage Design
A2: eQTY: Project Area (Acres)
A4: Project | B4: FCT MHRs | C4: eQTY | D4: Unit | E4: Production | F4: Applicable Job | G4: Custom
A5: IH 820 Southeast Connector | B5: 141161 | C5: 872 | D5: AC | E5: =B5/C5 -> 161.88188 | F5: Yes | G5: =IF(F5="Yes",E5,"") -> 161.88188
A6: BC Highway 1 | B6: 2209 | C6: 3.3 | D6: AC | E6: =B6/C6 -> 669.39394
A7: BC Highway 5 | B7: 4948 | C7: 16 | D7: AC | E7: =B7/C7 -> 309.25
A8: Federal Way Link Extension | B8: 122527 | C8: 104 | D8: AC | E8: =B8/C8 -> 1178.1442
A9: Foothill Phase 2A LRT | B9: 7420 | C9: 133 | D9: AC | E9: =B9/C9 -> 55.789474
A10: Foothill Phase 2B1 LRT | B10: 72738 | C10: 119 | D10: AC | E10: =B10/C10 -> 611.2437
A11: I-15 Tropicana | B11: 14493 | C11: 194 | D11: AC | E11: =B11/C11 -> 74.706186 | F11: Yes | G11: =IF(F11="Yes",E11,"") -> 74.706186
A12: I-17 Anthem | B12: 47947 | C12: 2171 | D12: AC | E12: =B12/C12 -> 22.085214 | F12: Yes | G12: =IF(F12="Yes",E12,"") -> 22.085214
A13: Ottawa LRT | B13: 11503 | C13: 560 | D13: AC | E13: =B13/C13 -> 20.541071
A14: US 97 | B14: 7787 | C14: 33 | D14: AC | E14: =B14/C14 -> 235.9697 | F14: Yes | G14: =IF(F14="Yes",E14,"") -> 235.9697
A15: 264th Street Interchange | B15: 11783 | C15: 193 | D15: AC | E15: =B15/C15 -> 61.051813 | F15: Yes | G15: =IF(F15="Yes",E15,"") -> 61.051813
A18: Productions (Project Qty) | C18: =B21 -> 121.5 | D18: AC | E18: =IFERROR(E46*(B21^E47),0) -> 148.26041 | G18: =IFERROR(F46*(B21^F47),0) -> 117.28878
A20: Input / Output
A21: Key Quantity (Column D) | B21: ='Summary - MH'!D6 -> 121.5
A22: Total MHR (All Projects) | B22: =B21*E18 -> 18013.639
A23: Total MHR (Custom Projects) | B23: =C18*G18 -> 14250.587
E45: Open | F45: Custom
B46: Average | C46: =AVERAGE(E5:E15) -> 309.09611 | E46: {=EXP(INDEX(LINEST(LN(E5:E15),LN(C5:C15),,),1,2))} -> 1665.9222 | F46: {=IFERROR(EXP(INDEX(LINEST(LN(_xlfn._xlws.FILTER(G5:G15, (C5:C15>0)*(G5:G15>0))), LN(_xlfn._xlws.FILTER(C5:C15, (C5:C15>0)*(G5:G15>0)))), 1, 2)),0)} -> 766.397
B47: Standard Dev. | C47: =STDEV(E5:E15) -> 367.37447 | E47: {=INDEX(LINEST(LN(E5:E15),LN(C5:C15),,),1)} -> -0.50400148 | F47: {=IFERROR(INDEX(LINEST(LN(_xlfn._xlws.FILTER(G5:G15, (C5:C15>0)*(G5:G15>0))),LN(_xlfn._xlws.FILTER(C5:C15, (C5:C15>0)*(G5:G15>0)))),1),0)} -> -0.3910614

Sheet MOT
A1: Maintenance of Traffic (MOT) Design
A2: eQTY: Alignment Length (LF)
A4: Project | B4: FCT MHRs | C4: eQTY | D4: Unit | E4: Production | F4: Applicable Job | G4: Custom
A5: IH 820 Southeast Connector | B5: 170668 | C5: 550674 | D5: LF | E5: =B5/C5 -> 0.30992565 | F5: Yes | G5: =IF(F5="Yes",E5,"") -> 0.30992565
A6: BC Highway 1 | B6: 3645 | C6: 1120 | D6: LF | E6: =B6/C6 -> 3.2544643
A7: BC Highway 5 | B7: 1050 | C7: 2300 | D7: LF | E7: =B7/C7 -> 0.45652174
A8: Federal Way Link Extension | B8: 32305 | C8: 83559 | D8: LF | E8: =B8/C8 -> 0.38661305
A9: Foothill Phase 2A LRT | B9: 3500 | C9: 25667 | D9: LF | E9: =B9/C9 -> 0.13636187
A10: Foothill Phase 2B1 LRT | B10: 7873 | C10: 17105 | D10: LF | E10: =B10/C10 -> 0.46027477
A11: I-15 Tropicana | B11: 11263 | C11: 48206 | D11: LF | E11: =B11/C11 -> 0.23364311 | F11: Yes | G11: =IF(F11="Yes",E11,"") -> 0.23364311
A12: I-17 Anthem | B12: 13867 | C12: 325987 | D12: LF | E12: =B12/C12 -> 0.042538506 | F12: Yes | G12: =IF(F12="Yes",E12,"") -> 0.042538506
A13: Ottawa LRT | B13: 72414 | C13: 547047 | D13: LF | E13: =B13/C13 -> 0.13237254
A14: US 97 | B14: 7364 | C14: 107830 | D14: LF | E14: =B14/C14 -> 0.068292683 | F14: Yes | G14: =IF(F14="Yes",E14,"") -> 0.068292683
A15: 264th Street Interchange | B15: 25407 | C15: 51920 | D15: LF | E15: =B15/C15 -> 0.489349 | F15: Yes | G15: =IF(F15="Yes",E15,"") -> 0.489349
A18: Productions (Project Qty) | C18: =B21 -> 34910 | D18: LF | E18: =IFERROR(E46*(B21^E47),0) -> 0.30161938 | G18: =IFERROR(F46*(B21^F47),0) -> 0.24530036
A20: Input / Output
A21: Key Quantity (Column D) | B21: ='Summary - MH'!D8 -> 34910
A22: Total MHR (All Projects) | B22: =B21*E18 -> 10529.532
A23: Total MHR (Custom Projects) | B23: =C18*G18 -> 8563.4357
E45: Open | F45: Custom
B46: Average | C46: =AVERAGE(E5:E15) -> 0.54275975 | E46: {=EXP(INDEX(LINEST(LN(E5:E15),LN(C5:C15),,),1,2))} -> 21.656292 | F46: {=IFERROR(EXP(INDEX(LINEST(LN(_xlfn._xlws.FILTER(G5:G15, (C5:C15>0)*(G5:G15>0))), LN(_xlfn._xlws.FILTER(C5:C15, (C5:C15>0)*(G5:G15>0)))), 1, 2)),0)} -> 6.6224672
B47: Standard Dev. | C47: =STDEV(E5:E15) -> 0.91397477 | E47: {=INDEX(LINEST(LN(E5:E15),LN(C5:C15),,),1)} -> -0.40857261 | F47: {=IFERROR(INDEX(LINEST(LN(_xlfn._xlws.FILTER(G5:G15, (C5:C15>0)*(G5:G15>0))),LN(_xlfn._xlws.FILTER(C5:C15, (C5:C15>0)*(G5:G15>0)))),1),0)} -> -0.31506437

Sheet RDWY
A1: Roadway Design
A2: eQTY: Alignment Length (LF)
A4: Project | B4: FCT MHRs | C4: eQTY | D4: Unit | E4: Production | F4: Applicable Job | G4: Custom
A5: IH 820 Southeast Connector | B5: 133332 | C5: 550674 | D5: LF | E5: =B5/C5 -> 0.2421251 | F5: Yes | G5: =IF(F5="Yes",E5,"") -> 0.2421251
A6: BC Highway 1 | B6: 4556 | C6: 1120 | D6: LF | E6: =B6/C6 -> 4.0678571
A7: BC Highway 5 | B7: 6097 | C7: 2300 | D7: LF | E7: =B7/C7 -> 2.6508696
A8: Federal Way Link Extension | B8: 74720 | C8: 165248 | D8: LF | E8: =B8/C8 -> 0.45216886
A9: Foothill Phase 2A LRT | B9: 13279 | C9: 180566 | D9: LF | E9: =B9/C9 -> 0.073540977
A10: Foothill Phase 2B1 LRT | B10: 58164 | C10: 120338 | D10: LF | E10: =B10/C10 -> 0.4833386
A11: I-15 Tropicana | B11: 24245 | C11: 48206 | D11: LF | E11: =B11/C11 -> 0.50294569 | F11: Yes | G11: =IF(F11="Yes",E11,"") -> 0.50294569
A12: I-17 Anthem | B12: 53211 | C12: 325987 | D12: LF | E12: =B12/C12 -> 0.16323044 | F12: Yes | G12: =IF(F12="Yes",E12,"") -> 0.16323044
A13: Ottawa LRT | B13: 192084 | C13: 556235 | D13: LF | E13: =B13/C13 -> 0.34532886
A14: Tijuana River Barrier | B14: 547 | C14: 2807 | D14: LF | E14: =B14/C14 -> 0.19486997
A15: 30 Crossing | B15: 40907 | C15: 57768 | D15: LF | E15: =B15/C15 -> 0.70812561 | F15: Yes | G15: =IF(F15="Yes",E15,"") -> 0.70812561
A16: CHPE Transmission | B16: 3410 | C16: 23450 | D16: LF | E16: =B16/C16 -> 0.14541578
A17: US 97 | B17: 21330 | C17: 102183 | D17: LF | E17: =B17/C17 -> 0.20874314 | F17: Yes | G17: =IF(F17="Yes",E17,"") -> 0.20874314
A18: 264th Street Interchange | B18: 26964 | C18: 51920 | D18: LF | E18: =B18/C18 -> 0.51933744 | F18: Yes | G18: =IF(F18="Yes",E18,"") -> 0.51933744
A21: Productions (Project Qty) | C21: =B24 -> 34910 | D21: LF | E21: =IFERROR(E49*(B24^E50),0) -> 0.45342434 | G21: =IFERROR(F49*(B24^F50),0) -> 0.58426654
A23: Input / Output
A24: Key Quantity (Column D) | B24: ='Summary - MH'!D9 -> 34910
A25: Total MHR (All Projects) | B25: =B24*E21 -> 15829.044
A26: Total MHR (Custom Projects) | B26: =C21*G21 -> 20396.745
E48: Open | F48: Custom
B49: Average | C49: =AVERAGE(E5:E18) -> 0.76842123 | E49: {=EXP(INDEX(LINEST(LN(E5:E18),LN(C5:C18),,),1,2))} -> 14.434496 | F49: {=IFERROR(EXP(INDEX(LINEST(LN(_xlfn._xlws.FILTER(G5:G18, (C5:C18>0)*(G5:G18>0))), LN(_xlfn._xlws.FILTER(C5:C18, (C5:C18>0)*(G5:G18>0)))), 1, 2)),0)} -> 62.908558
B50: Standard Dev. | C50: =STDEV(E5:E18) -> 1.1463245 | E50: {=INDEX(LINEST(LN(E5:E18),LN(C5:C18),,),1)} -> -0.33081959 | F50: {=IFERROR(INDEX(LINEST(LN(_xlfn._xlws.FILTER(G5:G18, (C5:C18>0)*(G5:G18>0))),LN(_xlfn._xlws.FILTER(C5:C18, (C5:C18>0)*(G5:G18>0)))),1),0)} -> -0.4473082

Sheet TRF
A1: Traffic Design
A2: eQTY: Alignment Length (LF)
A4: Project | B4: FCT MHRs | C4: eQTY | D4: Unit | E4: Production | F4: Applicable Job | G4: Custom
A5: IH 820 Southeast Connector | B5: 43833 | C5: 550674 | D5: LF | E5: =B5/C5 -> 0.079598819 | F5: Yes | G5: =IF(F5="Yes",E5,"") -> 0.079598819
A6: Federal Way Link Extension | B6: 42037 | C6: 83559 | D6: LF | E6: =B6/C6 -> 0.50308165
A7: Foothill Phase 2A LRT | B7: 4284 | C7: 25667 | D7: LF | E7: =B7/C7 -> 0.16690692
A8: Foothill Phase 2B1 LRT | B8: 12410 | C8: 17105 | D8: LF | E8: =B8/C8 -> 0.72551885
A9: I-15 Tropicana | B9: 27602 | C9: 48206 | D9: LF | E9: =B9/C9 -> 0.57258433 | F9: Yes | G9: =IF(F9="Yes",E9,"") -> 0.57258433
A10: I-17 Anthem | B10: 12223 | C10: 325987 | D10: LF | E10: =B10/C10 -> 0.03749536 | F10: Yes | G10: =IF(F10="Yes",E10,"") -> 0.03749536
A11: 30 Crossing | B11: 18882 | C11: 57768 | D11: LF | E11: =B11/C11 -> 0.32685916 | F11: Yes | G11: =IF(F11="Yes",E11,"") -> 0.32685916
A12: US 97 | B12: 1803 | C12: 102183 | D12: LF | E12: =B12/C12 -> 0.017644814 | F12: Yes | G12: =IF(F12="Yes",E12,"") -> 0.017644814
A13: 264th Street Interchange | B13: 5649 | C13: 51920 | D13: LF | E13: =B13/C13 -> 0.108802 | F13: Yes | G13: =IF(F13="Yes",E13,"") -> 0.108802
A16: Productions (Project Qty) | C16: =B19 -> 34910 | D16: LF | E16: =IFERROR(E44*(B19^E45),0) -> 0.27708946 | G16: =IFERROR(F44*(B19^F45),0) -> 0.22578174
A18: Input / Output
A19: Key Quantity (Column D) | B19: ='Summary - MH'!D10 -> 34910
A20: Total MHR (All Projects) | B20: =B19*E16 -> 9673.1929
A21: Total MHR (Custom Projects) | B21: =C16*G16 -> 7882.0406
E43: Open | F43: Custom
B44: Average | C44: =AVERAGE(E5:E13) -> 0.28205466 | E44: {=EXP(INDEX(LINEST(LN(E5:E13),LN(C5:C13),,),1,2))} -> 415.79614 | F44: {=IFERROR(EXP(INDEX(LINEST(LN(_xlfn._xlws.FILTER(G5:G13, (C5:C13>0)*(G5:G13>0))), LN(_xlfn._xlws.FILTER(C5:C13, (C5:C13>0)*(G5:G13>0)))), 1, 2)),0)} -> 226.6415
B45: Standard Dev. | C45: =STDEV(E5:E13) -> 0.26122644 | E45: {=INDEX(LINEST(LN(E5:E13),LN(C5:C13),,),1)} -> -0.69916256 | F45: {=IFERROR(INDEX(LINEST(LN(_xlfn._xlws.FILTER(G5:G13, (C5:C13>0)*(G5:G13>0))),LN(_xlfn._xlws.FILTER(C5:C13, (C5:C13>0)*(G5:G13>0)))),1),0)} -> -0.66072722

Sheet UTL
A1: Utilities Design (no coordination time included)
A2: eQTY: Relocation Count (EA)
A4: Project | B4: FCT MHRs | C4: eQTY | D4: Unit | E4: Production | F4: Applicable Job | G4: Custom
A5: IH 820 Southeast Connector | B5: 108899 | C5: 384 | D5: EA | E5: =B5/C5 -> 283.59115 | F5: Yes | G5: =IF(F5="Yes",E5,"") -> 283.59115
A6: Foothill Phase 2B1 LRT | B6: 18896 | C6: 70 | D6: EA | E6: =B6/C6 -> 269.94286
A7: I-15 Tropicana | B7: 6374 | C7: 48 | D7: EA | E7: =B7/C7 -> 132.79167 | F7: Yes | G7: =IF(F7="Yes",E7,"") -> 132.79167
A8: US 97 | B8: 3336 | C8: 11 | D8: EA | E8: =B8/C8 -> 303.27273 | F8: Yes | G8: =IF(F8="Yes",E8,"") -> 303.27273
A9: 264th Street Interchange | B9: 1465 | C9: 5 | D9: EA | E9: =B9/C9 -> 293 | F9: Yes | G9: =IF(F9="Yes",E9,"") -> 293
A12: Productions (Project Qty) | C12: =B15 -> 15 | D12: EA | E12: =IFERROR(E40*(B15^E41),0) -> 253.51996 | G12: =IFERROR(F40*(B15^F41),0) -> 247.97533
A14: Input / Output
A15: Key Quantity (Column D) | B15: ='Summary - MH'!D11 -> 15
A16: Total MHR (All Projects) | B16: =B15*E12 -> 3802.7994
A17: Total MHR (Custom Projects) | B17: =C12*G12 -> 3719.6299
E39: Open | F39: Custom
B40: Average | C40: =AVERAGE(E5:E9) -> 256.51968 | E40: {=EXP(INDEX(LINEST(LN(E5:E9),LN(C5:C9),,),1,2))} -> 276.91278 | F40: {=IFERROR(EXP(INDEX(LINEST(LN(_xlfn._xlws.FILTER(G5:G9, (C5:C9>0)*(G5:G9>0))), LN(_xlfn._xlws.FILTER(C5:C9, (C5:C9>0)*(G5:G9>0)))), 1, 2)),0)} -> 276.9247
B41: Standard Dev. | C41: =STDEV(E5:E9) -> 70.246581 | E41: {=INDEX(LINEST(LN(E5:E9),LN(C5:C9),,),1)} -> -0.032591722 | F41: {=IFERROR(INDEX(LINEST(LN(_xlfn._xlws.FILTER(G5:G9, (C5:C9>0)*(G5:G9>0))),LN(_xlfn._xlws.FILTER(C5:C9, (C5:C9>0)*(G5:G9>0)))),1),0)} -> -0.040773389

Sheet RWAL
A1: Retaining Wall Design
A2: eQTY: Wall Area (SF)
A4: Project | B4: FCT MHRs | C4: eQTY | D4: Unit | E4: Production | F4: Applicable Job | G4: Custom
A5: IH 820 Southeast Connector | B5: 48960 | C5: 1169432 | D5: SF | E5: =B5/C5 -> 0.041866479 | F5: Yes | G5: =IF(F5="Yes",E5,"") -> 0.041866479
A6: Federal Way Link Extension | B6: 54751 | C6: 434037 | D6: SF | E6: =B6/C6 -> 0.12614362
A7: Foothill Phase 2B1 LRT | B7: 18592 | C7: 377619 | D7: SF | E7: =B7/C7 -> 0.049234811
A8: I-15 Tropicana | B8: 4724 | C8: 95796 | D8: SF | E8: =B8/C8 -> 0.049313124 | F8: Yes | G8: =IF(F8="Yes",E8,"") -> 0.049313124
A9: 30 Crossing | B9: 3905 | C9: 42336 | D9: SF | E9: =B9/C9 -> 0.092238284 | F9: Yes | G9: =IF(F9="Yes",E9,"") -> 0.092238284
A10: US 97 | B10: 696 | C10: 30039 | D10: SF | E10: =B10/C10 -> 0.023169879 | F10: Yes | G10: =IF(F10="Yes",E10,"") -> 0.023169879
A13: Productions (Project Qty) | C13: =B16 -> 10310 | D13: SF | E13: =IFERROR(E41*(B16^E42),0) -> 0.042003279 | G13: =IFERROR(F41*(B16^F42),0) -> 0.045916918
A15: Input / Output
A16: Key Quantity (Column D) | B16: ='Summary - MH'!D13 -> 10310
A17: Total MHR (All Projects) | B17: =B16*E13 -> 433.05381
A18: Total MHR (Custom Projects) | B18: =C13*G13 -> 473.40342
E40: Open | F40: Custom
B41: Average | C41: =AVERAGE(E5:E10) -> 0.063661033 | E41: {=EXP(INDEX(LINEST(LN(E5:E10),LN(C5:C10),,),1,2))} -> 0.017334082 | F41: {=IFERROR(EXP(INDEX(LINEST(LN(_xlfn._xlws.FILTER(G5:G10, (C5:C10>0)*(G5:G10>0))), LN(_xlfn._xlws.FILTER(C5:C10, (C5:C10>0)*(G5:G10>0)))), 1, 2)),0)} -> 0.046252041
B42: Standard Dev. | C42: =STDEV(E5:E10) -> 0.03807689 | E42: {=INDEX(LINEST(LN(E5:E10),LN(C5:C10),,),1)} -> 0.095778111 | F42: {=IFERROR(INDEX(LINEST(LN(_xlfn._xlws.FILTER(G5:G10, (C5:C10>0)*(G5:G10>0))),LN(_xlfn._xlws.FILTER(C5:C10, (C5:C10>0)*(G5:G10>0)))),1),0)} -> -0.00078693469

Sheet NWAL
A1: Noise Wall Design
A2: eQTY: Wall Area (SF)
A4: Project | B4: FCT MHRs | C4: eQTY | D4: Unit | E4: Production | F4: Applicable Job | G4: Custom
A5: IH 820 Southeast Connector | B5: 10909 | C5: 190048 | D5: SF | E5: =B5/C5 -> 0.057401288 | F5: Yes | G5: =IF(F5="Yes",E5,"") -> 0.057401288
A6: Foothill Phase 2B1 LRT | B6: 5339 | C6: 241020 | D6: SF | E6: =B6/C6 -> 0.022151689 | F6: Yes | G6: =IF(F6="Yes",E6,"") -> 0.022151689
A13: Productions (Project Qty) | C13: =B16 -> 0 | D13: SF | E13: =IFERROR(E41*(B16^E42),0) -> 0 | G13: =IFERROR(F41*(B16^F42),0) -> 0
A15: Input / Output
A16: Key Quantity (Column D) | B16: ='Summary - MH'!D14 -> 0
A17: Total MHR (All Projects) | B17: =B16*E13 -> 0
A18: Total MHR (Custom Projects) | B18: =C13*G13 -> 0
E40: Open | F40: Custom
B41: Average | C41: =AVERAGE(E5:E6) -> 0.039776488 | E41: {=EXP(INDEX(LINEST(LN(E5:E6),LN(C5:C6),,),1,2))} -> 8.185276e+19 | F41: {=IFERROR(EXP(INDEX(LINEST(LN(_xlfn._xlws.FILTER(G5:G6, (C5:C6>0)*(G5:G6>0))), LN(_xlfn._xlws.FILTER(C5:C6, (C5:C6>0)*(G5:G6>0)))), 1, 2)),0)} -> 8.185276e+19
B42: Standard Dev. | C42: =STDEV(E5:E6) -> 0.024925231 | E42: {=INDEX(LINEST(LN(E5:E6),LN(C5:C6),,),1)} -> -4.0073233 | F42: {=IFERROR(INDEX(LINEST(LN(_xlfn._xlws.FILTER(G5:G6, (C5:C6>0)*(G5:G6>0))),LN(_xlfn._xlws.FILTER(C5:C6, (C5:C6>0)*(G5:G6>0)))),1),0)} -> -4.0073233

Sheet STR
A1: Bridge Structures
A2: eQTY: Bridge Deck Area (SF)
A4: Project | B4: Structure Name | C4: FCT MHRs | D4: eQTY | E4: Unit | F4: Production | G4: Applicable Job | H4: Custom | I4: Type | J4: Span Arrangement | K4: Scope
A5: IH 820 Southeast Connector | B5: Bridge 036 | C5: 3389 | D5: 240178 | E5: SF | F5: =C5/D5 -> 0.014110368 | G5: Multi-Span | H5: =IF(G5="Yes",F5,"") | I5: PC Girder | J5: Multi-Span | K5: New/Reconstruct
A6: IH 820 Southeast Connector | B6: Bridge 037 | C6: 7087 | D6: 199692 | E6: SF | F6: =C6/D6 -> 0.035489654 | G6: Multi-Span | H6: =IF(G6="Yes",F6,"") | I6: PC Girder | J6: Multi-Span | K6: New/Reconstruct
A7: IH 820 Southeast Connector | B7: Bridge 047 | C7: 4409 | D7: 143290 | E7: SF | F7: =C7/D7 -> 0.030769768 | G7: Multi-Span | H7: =IF(G7="Yes",F7,"") | I7: PC Girder | J7: Multi-Span | K7: New/Reconstruct
A8: IH 820 Southeast Connector | B8: Bridge 025 | C8: 5202 | D8: 136169 | E8: SF | F8: =C8/D8 -> 0.038202528 | G8: Multi-Span | H8: =IF(G8="Yes",F8,"") | I8: PC Girder | J8: Multi-Span | K8: New/Reconstruct
A9: IH 820 Southeast Connector | B9: Bridge 024 | C9: 3727 | D9: 116988 | E9: SF | F9: =C9/D9 -> 0.031857968 | G9: Multi-Span | H9: =IF(G9="Yes",F9,"") | I9: PC Girder | J9: Multi-Span | K9: New/Reconstruct
A10: IH 820 Southeast Connector | B10: Bridge 035 | C10: 3811 | D10: 89646 | E10: SF | F10: =C10/D10 -> 0.042511657 | G10: Multi-Span | H10: =IF(G10="Yes",F10,"") | I10: PC Girder | J10: Multi-Span | K10: New/Reconstruct
A11: IH 820 Southeast Connector | B11: Bridge 044 | C11: 2421 | D11: 66662 | E11: SF | F11: =C11/D11 -> 0.036317542 | G11: Multi-Span | H11: =IF(G11="Yes",F11,"") | I11: PC Girder | J11: Multi-Span | K11: New/Reconstruct
A12: IH 820 Southeast Connector | B12: Bridge 009 | C12: 2369 | D12: 55663 | E12: SF | F12: =C12/D12 -> 0.04255969 | G12: Multi-Span | H12: =IF(G12="Yes",F12,"") | I12: PC Girder | J12: Multi-Span | K12: New/Reconstruct
A13: IH 820 Southeast Connector | B13: Bridge 52A | C13: 2781 | D13: 47438 | E13: SF | F13: =C13/D13 -> 0.058623888 | G13: Multi-Span | H13: =IF(G13="Yes",F13,"") | I13: PC Girder | J13: Multi-Span | K13: New/Reconstruct
A14: IH 820 Southeast Connector | B14: Bridge 029 | C14: 2329 | D14: 47402 | E14: SF | F14: =C14/D14 -> 0.049132948 | G14: Multi-Span | H14: =IF(G14="Yes",F14,"") | I14: PC Girder | J14: Multi-Span | K14: New/Reconstruct
A15: IH 820 Southeast Connector | B15: Bridge 043 | C15: 2365 | D15: 45178 | E15: SF | F15: =C15/D15 -> 0.052348488 | G15: Multi-Span | H15: =IF(G15="Yes",F15,"") | I15: PC Girder | J15: Multi-Span | K15: New/Reconstruct
A16: IH 820 Southeast Connector | B16: Bridge 027 | C16: 2426 | D16: 42282 | E16: SF | F16: =C16/D16 -> 0.057376661 | G16: Multi-Span | H16: =IF(G16="Yes",F16,"") | I16: PC Girder | J16: Multi-Span | K16: New/Reconstruct
... A42: IH 820 Southeast Connector | B42: Bridge 032 | C42: 967 | D42: 4360 | E42: SF | F42: =C42/D42 -> 0.22178899 | G42: Single Span | H42: =IF(G42="Yes",F42,"") | I42: PC Girder | J42: Single-Span | K42: New/Reconstruct
A43: IH 820 Southeast Connector | B43: Bridge 041 | C43: 1586 | D43: 3646 | E43: SF | F43: =C43/D43 -> 0.43499726 | H43: =IF(G43="Yes",F43,"") | I43: Steel Girder | J43: Multi-Span | K43: Widening/Rehab
A44: Ottawa LRT | B44: PC Girder | C44: 47300 | D44: 193570 | E44: SF | F44: =C44/D44 -> 0.24435605 | H44: =IF(G44="Yes",F44,"") | I44: PC Girder | J44: Multi-Span | K44: New/Reconstruct
A45: Federal Way Link Extension | B45: Design S2.01 - Elevated Guideway - Structure B | C45: 22690.8 | D45: 116016.5 | E45: SF | F45: =C45/D45 -> 0.19558252 | H45: =IF(G45="Yes",F45,"") | I45: PC Girder | J45: Multi-Span | K45: New/Reconstruct
A46: Federal Way Link Extension | B46: Design S3.04 - Elevated Guideway - Structure G | C46: 19540.9 | D46: 96134 | E46: SF | F46: =C46/D46 -> 0.20326731 | H46: =IF(G46="Yes",F46,"") | I46: CIP Girder | J46: Multi-Span | K46: New/Reconstruct
A47: Federal Way Link Extension | B47: Design S1.01 - Elevated Guideway - Structure A | C47: 31022.599 | D47: 82359 | E47: SF | F47: =C47/D47 -> 0.37667528 | H47: =IF(G47="Yes",F47,"") | I47: PC Girder | J47: Multi-Span | K47: New/Reconstruct
A48: I-15 Tropicana | B48: D11 | C48: 5819 | D48: 46957 | E48: SF | F48: =C48/D48 -> 0.12392189 | G48: Multi-Span | H48: =IF(G48="Yes",F48,"") | I48: PC Girder | J48: Multi-Span | K48: New/Reconstruct
A49: Federal Way Link Extension | B49: Design S3.02 - Elevated Guideway - Structure E | C49: 6590 | D49: 34452 | E49: SF | F49: =C49/D49 -> 0.19128062 | H49: =IF(G49="Yes",F49,"") | I49: CIP Girder | J49: Multi-Span | K49: New/Reconstruct
A50: Federal Way Link Extension | B50: Design S2.02B - Elevated Guideway - Structure C | C50: 43403.25 | D50: 39134 | E50: SF | F50: =C50/D50 -> 1.1090931 | H50: =IF(G50="Yes",F50,"") | I50: PC Girder | J50: Multi-Span | K50: New/Reconstruct
A51: Federal Way Link Extension | B51: Design S3.03 - Elevated Guideway - Structure F | C51: 2426.25 | D51: 16052 | E51: SF | F51: =C51/D51 -> 0.15114939 | H51: =IF(G51="Yes",F51,"") | I51: CIP Girder | J51: Multi-Span | K51: New/Reconstruct
A52: Federal Way Link Extension | B52: Design S3.01 - Elevated Guideway - Structure D | C52: 4320.75 | D52: 16045 | E52: SF | F52: =C52/D52 -> 0.2692895 | H52: =IF(G52="Yes",F52,"") | I52: CIP Girder | J52: Multi-Span | K52: New/Reconstruct
A53: Foothill Phase 2B1 LRT | B53: LRT Lone Hill Ave | C53: 4736 | D53: 10674.33 | E53: SF | F53: =C53/D53 -> 0.44368124 | H53: =IF(G53="Yes",F53,"") | I53: Box Girder | J53: Multi-Span | K53: New/Reconstruct
A54: Foothill Phase 2B1 LRT | B54: LRT Foothill Blvd-Grand Ave | C54: 3910 | D54: 8103.33 | E54: SF | F54: =C54/D54 -> 0.48251768 | H54: =IF(G54="Yes",F54,"") | I54: Box Girder | J54: Single-Span | K54: New/Reconstruct
A55: Foothill Phase 2B1 LRT | B55: LRT Bonita Ave - Cataract Ave | C55: 2206 | D55: 7283.33 | E55: SF | F55: =C55/D55 -> 0.30288343 | H55: =IF(G55="Yes",F55,"") | I55: Box Girder | J55: Single-Span | K55: New/Reconstruct
A56: Foothill Phase 2B1 LRT | B56: LRT U.S. State Route 66 | C56: 5877 | D56: 5781.48 | E56: SF | F56: =C56/D56 -> 1.0165217 | H56: =IF(G56="Yes",F56,"") | I56: Box Girder | J56: Multi-Span | K56: New/Reconstruct
A57: I-15 Tropicana | B57: D14 | C57: 3641 | D57: 26805 | E57: SF | F57: =C57/D57 -> 0.13583287 | G57: Single Span | H57: =IF(G57="Yes",F57,"") | I57: PC Girder | J57: Single-Span | K57: New/Reconstruct
A58: Foothill Phase 2B1 LRT | B58: FRT San Dimas Wash | C58: 2093 | D58: 1900.5 | E58: SF | F58: =C58/D58 -> 1.1012891 | H58: =IF(G58="Yes",F58,"") | I58: Steel Girder | J58: Single-Span | K58: New/Reconstruct
A59: Foothill Phase 2B1 LRT | B59: LRT Big Dalton Wash | C59: 1978 | D59: 1674 | E59: SF | F59: =C59/D59 -> 1.181601 | H59: =IF(G59="Yes",F59,"") | I59: Box Girder | J59: Single-Span | K59: New/Reconstruct
A60: Foothill Phase 2B1 LRT | B60: LRT Live Oak Channel | C60: 1889 | D60: 1550 | E60: SF | F60: =C60/D60 -> 1.2187097 | H60: =IF(G60="Yes",F60,"") | I60: Box Girder | J60: Single-Span | K60: New/Reconstruct
A61: Foothill Phase 2B1 LRT | B61: FRT Big Dalton Wash | C61: 1931 | D61: 941.22 | E61: SF | F61: =C61/D61 -> 2.0515926 | H61: =IF(G61="Yes",F61,"") | I61: Box Girder | J61: Single-Span | K61: New/Reconstruct
A62: Foothill Phase 2B1 LRT | B62: FRT Thompson Creek Channel | C62: 1552 | D62: 698.15 | E62: SF | F62: =C62/D62 -> 2.223018 | H62: =IF(G62="Yes",F62,"") | I62: Box Girder | J62: Single-Span | K62: New/Reconstruct
A63: Foothill Phase 2B1 LRT | B63: FRT Live Oak Channel | C63: 1171 | D63: 530.47 | E63: SF | F63: =C63/D63 -> 2.2074764 | H63: =IF(G63="Yes",F63,"") | I63: Box Girder | J63: Single-Span | K63: New/Reconstruct
A64: Federal Way Link Extension | B64: Design S1.03 - SR99 Bridge | C64: 3372 | D64: 24972 | E64: SF | F64: =C64/D64 -> 0.13503123 | H64: =IF(G64="Yes",F64,"") | I64: PC Girder | J64: Multi-Span | K64: New/Reconstruct
A65: I-15 Tropicana | B65: D13 | C65: 9398 | D65: 18226 | E65: SF | F65: =C65/D65 -> 0.515637 | G65: Single Span | H65: =IF(G65="Yes",F65,"") | I65: PC Girder | J65: Single-Span | K65: New/Reconstruct
A66: I-17 Anthem | B66: 2B4 | C66: 3718 | D66: 15442 | E66: SF | F66: =C66/D66 -> 0.24077192 | G66: Multi-Span | H66: =IF(G66="Yes",F66,"") | I66: PC Girder | J66: Multi-Span | K66: Widening/Rehab
...

Sheet MSRT
A1: Miscellaneous Structure Design
A2: eQTY: Spent MHRs of Roadway, Drainage and Traffic
A4: Project | B4: FCT MHRs | C4: eQTY | D4: Unit | E4: Production | F4: Applicable Job | G4: Custom
A5: IH 820 Southeast Connector | B5: 19110 | C5: 378295 | D5: MHR | E5: =B5/C5 -> 0.050516132 | F5: Yes | G5: =IF(F5="Yes",E5,"") -> 0.050516132
A6: BC Highway 1 | B6: 738 | C6: 6765 | D6: MHR | E6: =B6/C6 -> 0.10909091
A7: Federal Way Link Extension | B7: 9945 | C7: 294035 | D7: MHR | E7: =B7/C7 -> 0.033822504
A8: Foothill Phase 2B1 LRT | B8: 12927 | C8: 166681 | D8: MHR | E8: =B8/C8 -> 0.07755533
A9: I-15 Tropicana | B9: 4145 | C9: 71064 | D9: MHR | E9: =B9/C9 -> 0.058327705 | F9: Yes | G9: =IF(F9="Yes",E9,"") -> 0.058327705
A10: I-17 Anthem | B10: 5004 | C10: 113381 | D10: MHR | E10: =B10/C10 -> 0.044134379 | F10: Yes | G10: =IF(F10="Yes",E10,"") -> 0.044134379
A11: 264th Street Interchange | B11: 1945 | C11: 44396 | D11: MHR | E11: =B11/C11 -> 0.043810253 | F11: Yes | G11: =IF(F11="Yes",E11,"") -> 0.043810253
A14: Productions (Project Qty) | C14: =B17 -> 42529.373 | D14: MHR | E14: =IFERROR(E42*(B17^E43),0) -> 0.064115291 | G14: =IFERROR(F42*(B17^F43),0) -> 0.047798526
A16: Input / Output
A17: Key Quantity (Column D) | B17: ='Summary - MH'!D18 -> 42529.373
A18: Total MHR (All Projects) | B18: =B17*E14 -> 2726.7831
A19: Total MHR (Custom Projects) | B19: =C14*G14 -> 2032.8413
E41: Open | F41: Custom
B42: Average | C42: =AVERAGE(E5:E11) -> 0.059608173 | E42: {=EXP(INDEX(LINEST(LN(E5:E11),LN(C5:C11),,),1,2))} -> 0.50631878 | F42: {=IFERROR(EXP(INDEX(LINEST(LN(_xlfn._xlws.FILTER(G5:G11, (C5:C11>0)*(G5:G11>0))), LN(_xlfn._xlws.FILTER(C5:C11, (C5:C11>0)*(G5:G11>0)))), 1, 2)),0)} -> 0.037206026
B43: Standard Dev. | C43: =STDEV(E5:E11) -> 0.025848468 | E43: {=INDEX(LINEST(LN(E5:E11),LN(C5:C11),,),1)} -> -0.19389128 | F43: {=IFERROR(INDEX(LINEST(LN(_xlfn._xlws.FILTER(G5:G11, (C5:C11>0)*(G5:G11>0))),LN(_xlfn._xlws.FILTER(C5:C11, (C5:C11>0)*(G5:G11>0)))),1),0)} -> 0.023505838

Sheet GEO
A1: Geotechnical Design
A2: eQTY: Count of Transportation Structures (EA)
A4: Project | B4: FCT MHRs | C4: eQTY | D4: Unit | E4: Production | F4: Applicable Job | G4: Custom
A5: IH 820 Southeast Connector | B5: 47629 | C5: 274 | D5: EA | E5: =B5/C5 -> 173.82847 | F5: Yes | G5: =IF(F5="Yes",E5,"") -> 173.82847
A6: BC Highway 1 | B6: 1255 | C6: 2 | D6: EA | E6: =B6/C6 -> 627.5
A7: BC Highway 5 | B7: 4735 | C7: 8 | D7: EA | E7: =B7/C7 -> 591.875
A8: Federal Way Link Extension | B8: 33353 | C8: 127 | D8: EA | E8: =B8/C8 -> 262.62205
A9: Foothill Phase 2A LRT | B9: 6797 | C9: 19 | D9: EA | E9: =B9/C9 -> 357.73684
A10: Foothill Phase 2B1 LRT | B10: 98819 | C10: 99 | D10: EA | E10: =B10/C10 -> 998.17172
A11: I-15 Tropicana | B11: 9508 | C11: 33 | D11: EA | E11: =B11/C11 -> 288.12121 | F11: Yes | G11: =IF(F11="Yes",E11,"") -> 288.12121
A12: I-17 Anthem | B12: 23572 | C12: 110 | D12: EA | E12: =B12/C12 -> 214.29091 | F12: Yes | G12: =IF(F12="Yes",E12,"") -> 214.29091
A13: Tijuana River Barrier | B13: 951 | C13: 1 | D13: EA | E13: =B13/C13 -> 951
A14: US 97 | B14: 2900 | C14: 19 | D14: EA | E14: =B14/C14 -> 152.63158 | F14: Yes | G14: =IF(F14="Yes",E14,"") -> 152.63158
A15: 264th Street Interchange | B15: 7478 | C15: 6 | D15: EA | E15: =B15/C15 -> 1246.3333
A18: Productions (Project Qty) | C18: =B21 -> 12 | D18: EA | E18: =IFERROR(E46*(B21^E47),0) -> 482.25672 | G18: =IFERROR(F46*(B21^F47),0) -> 207.70012
A20: Input / Output
A21: Key Quantity (Column D) | B21: ='Summary - MH'!D19 -> 12
A22: Total MHR (All Projects) | B22: =B21*E18 -> 5787.0806
A23: Total MHR (Custom Projects) | B23: =C18*G18 -> 2492.4014
E45: Open | F45: Custom
B46: Average | C46: =AVERAGE(E5:E15) -> 533.10101 | E46: {=EXP(INDEX(LINEST(LN(E5:E15),LN(C5:C15),,),1,2))} -> 893.14709 | F46: {=IFERROR(EXP(INDEX(LINEST(LN(_xlfn._xlws.FILTER(G5:G15, (C5:C15>0)*(G5:G15>0))), LN(_xlfn._xlws.FILTER(C5:C15, (C5:C15>0)*(G5:G15>0)))), 1, 2)),0)} -> 217.58956
B47: Standard Dev. | C47: =STDEV(E5:E15) -> 380.97197 | E47: {=INDEX(LINEST(LN(E5:E15),LN(C5:C15),,),1)} -> -0.24800718 | F47: {=IFERROR(INDEX(LINEST(LN(_xlfn._xlws.FILTER(G5:G15, (C5:C15>0)*(G5:G15>0))),LN(_xlfn._xlws.FILTER(C5:C15, (C5:C15>0)*(G5:G15>0)))),1),0)} -> -0.01871911

Sheet SYS
A1: Systems
A2: eQTY: Track Alignment Length (TF)
A4: Project | B4: FCT MHRs | C4: eQTY | D4: Unit | E4: Production | F4: Applicable Job | G4: Custom
A5: Federal Way Link Extension | B5: 153825 | C5: 81688 | D5: TF | E5: =B5/C5 -> 1.8830795 | F5: Yes | G5: =IF(F5="Yes",E5,"") -> 1.8830795
A6: Foothill Phase 2A LRT | B6: 39239 | C6: 154899 | D6: TF | E6: =B6/C6 -> 0.25331991 | F6: Yes | G6: =IF(F6="Yes",E6,"") -> 0.25331991
A7: Foothill Phase 2B1 LRT | B7: 88715 | C7: 103233 | D7: TF | E7: =B7/C7 -> 0.85936668 | F7: Yes | G7: =IF(F7="Yes",E7,"") -> 0.85936668
A8: Ottawa LRT | B8: 135270 | C8: 167537 | D8: TF | E8: =B8/C8 -> 0.80740374
A12: Productions (Project Qty) | C12: =B15 -> 0 | D12: TF | E12: =IFERROR(E40*(B15^E41),0) -> 0 | G12: =IFERROR(F40*(B15^F41),0) -> 0
A14: Input / Output
A15: Key Quantity (Column D) | B15: ='Summary - MH'!D20 -> 0
A16: Total MHR (All Projects) | B16: =B15*E12 -> 0
A17: Total MHR (Custom Projects) | B17: =C12*G12 -> 0
E39: Open | F39: Custom
B40: Average | C40: =AVERAGE(E5:E8) -> 0.95079246 | E40: {=EXP(INDEX(LINEST(LN(E5:E8),LN(C5:C8),,),1,2))} -> 1.24199e+09 | F40: {=IFERROR(EXP(INDEX(LINEST(LN(_xlfn._xlws.FILTER(G5:G8, (C5:C8>0)*(G5:G8>0))), LN(_xlfn._xlws.FILTER(C5:C8, (C5:C8>0)*(G5:G8>0)))), 1, 2)),0)} -> 3.9606176e+15
B41: Standard Dev. | C41: =STDEV(E5:E8) -> 0.67934923 | E41: {=INDEX(LINEST(LN(E5:E8),LN(C5:C8),,),1)} -> -1.8120166 | F41: {=IFERROR(INDEX(LINEST(LN(_xlfn._xlws.FILTER(G5:G8, (C5:C8>0)*(G5:G8>0))),LN(_xlfn._xlws.FILTER(C5:C8, (C5:C8>0)*(G5:G8>0)))),1),0)} -> -3.1212287

Sheet TRK
A1: Track Design
A2: eQTY: Track Alignment Length (TF)
A4: Project | B4: FCT MHRs | C4: eQTY | D4: Unit | E4: Production | F4: Applicable Job | G4: Custom
A5: Federal Way Link Extension | B5: 55340 | C5: 81688 | D5: TF | E5: =B5/C5 -> 0.67745569 | F5: Yes | G5: =IF(F5="Yes",E5,"") -> 0.67745569
A6: Foothill Phase 2A LRT | B6: 8757 | C6: 154899 | D6: TF | E6: =B6/C6 -> 0.056533612 | F6: Yes | G6: =IF(F6="Yes",E6,"") -> 0.056533612
A7: Foothill Phase 2B1 LRT | B7: 6838 | C7: 103233 | D7: TF | E7: =B7/C7 -> 0.066238509 | F7: Yes | G7: =IF(F7="Yes",E7,"") -> 0.066238509
A8: Ottawa LRT | B8: 82275 | C8: 167537 | D8: TF | E8: =B8/C8 -> 0.49108555
A12: Productions (Project Qty) | C12: =B15 -> 0 | D12: TF | E12: =IFERROR(E40*(B15^E41),0) -> 0 | G12: =IFERROR(F40*(B15^F41),0) -> 0
A14: Input / Output
A15: Key Quantity (Column D) | B15: ='Summary - MH'!D21 -> 0
A16: Total MHR (All Projects) | B16: =B15*E12 -> 0
A17: Total MHR (Custom Projects) | B17: =C12*G12 -> 0
E39: Open | F39: Custom
B40: Average | C40: =AVERAGE(E5:E8) -> 0.32282834 | E40: {=EXP(INDEX(LINEST(LN(E5:E8),LN(C5:C8),,),1,2))} -> 10125.828 | F40: {=IFERROR(EXP(INDEX(LINEST(LN(_xlfn._xlws.FILTER(G5:G8, (C5:C8>0)*(G5:G8>0))), LN(_xlfn._xlws.FILTER(C5:C8, (C5:C8>0)*(G5:G8>0)))), 1, 2)),0)} -> 5.5284674e+16
B41: Standard Dev. | C41: =STDEV(E5:E8) -> 0.3113531 | E41: {=INDEX(LINEST(LN(E5:E8),LN(C5:C8),,),1)} -> -0.9304887 | F41: {=IFERROR(INDEX(LINEST(LN(_xlfn._xlws.FILTER(G5:G8, (C5:C8>0)*(G5:G8>0))),LN(_xlfn._xlws.FILTER(C5:C8, (C5:C8>0)*(G5:G8>0)))),1),0)} -> -3.4945374

Sheet ESDC
A1: Engineering Services During Construction (ESDC)
A2: eQTY: Anticipated Project Cost
A4: Project | B4: ESDC Cost | C4: eQTY | D4: Unit | E4: Production | F4: Applicable Job | G4: Custom | H4: Market | I4: City, State | J4: Country
A5: IH 820 Southeast Connector | B5: 23053.57 | C5: 1938485.1 | D5: K$ | E5: =B5/C5 -> 0.01189257 | F5: Yes | G5: =IF(F5="Yes",E5,"") -> 0.01189257 | H5: Transportation, Highway | I5: Fort Worth, TX | J5: USA
A6: Federal Way Link Extension | B6: 21188.27 | C6: 1376998.2 | D6: K$ | E6: =B6/C6 -> 0.01538729 | H6: Transit, Light Rail | I6: Federal Way, WA | J6: USA
A7: Foothill Phase 2A LRT | B7: 6232 | C7: 470813.24 | D7: K$ | E7: =B7/C7 -> 0.013236671 | H7: Transit, Light Rail | I7: San Dimas, CA | J7: USA
A8: Foothill Phase 2B1 LRT | B8: 8894.15 | C8: 836559.23 | D8: K$ | E8: =B8/C8 -> 0.010631823 | H8: Transit, Light Rail | I8: San Dimas, CA | J8: USA
A9: Ottawa LRT | B9: 52312.47 | C9: 3691276.9 | D9: K$ | E9: =B9/C9 -> 0.014171917 | H9: Transit, Light Rail | I9: Ottawa, ON | J9: CAN
A10: C-70 | B10: 15995.5 | C10: 1386636.6 | D10: K$ | E10: =B10/C10 -> 0.011535466 | F10: Yes | G10: =IF(F10="Yes",E10,"") -> 0.011535466 | H10: Transportation, Highway | I10: Denver, CO | J10: USA
A11: I-25 T-REX | B11: 9702.7 | C11: 1144655.1 | D11: K$ | E11: =B11/C11 -> 0.0084765275 | F11: Yes | G11: =IF(F11="Yes",E11,"") -> 0.0084765275 | H11: Transportation, Highway | I11: Denver, CO | J11: USA
A12: MoDOT 554 Bridges | B12: 3418.31 | C12: 405622.25 | D12: K$ | E12: =B12/C12 -> 0.0084273237 | H12: Transportation, Bridges | I12: Jefferson City, CO | J12: USA
A13: Geneva Road | B13: 347.6 | C13: 41533.16 | D13: K$ | E13: =B13/C13 -> 0.0083692163 | F13: Yes | G13: =IF(F13="Yes",E13,"") -> 0.0083692163 | H13: Transportation, Highway | I13: Orem, UT | J13: USA
A14: I-15 Corridor Reconstruction | B14: 10453.15 | C14: 1261222.9 | D14: K$ | E14: =B14/C14 -> 0.0082881071 | F14: Yes | G14: =IF(F14="Yes",E14,"") -> 0.0082881071 | H14: Transportation, Highway | I14: Salt Lake City, UT | J14: USA
A15: SR-202 | B15: 1276.02 | C15: 155588.42 | D15: K$ | E15: =B15/C15 -> 0.008201253 | F15: Yes | G15: =IF(F15="Yes",E15,"") -> 0.008201253 | H15: Transportation, Highway | I15: Phoenix, AZ | J15: USA
A16: DFW Connector | B16: 6439.08 | C16: 798052.8 | D16: K$ | E16: =B16/C16 -> 0.0080684887 | F16: Yes | G16: =IF(F16="Yes",E16,"") -> 0.0080684887 | H16: Transportation, Highway | I16: Dallas, TX | J16: USA
A17: PCCP | B17: 4673.55 | C17: 697958.72 | D17: K$ | E17: =B17/C17 -> 0.0066960264 | H17: Water, Pump Station | I17: New Orleans, LA | J17: USA
A18: Port Mann / Highway 1 | B18: 21056.55 | C18: 2388792.6 | D18: K$ | E18: =B18/C18 -> 0.008814725 | H18: Transportation, Bridges | I18: Vancoucer, BC | J18: CAN
A19: SR-520 Floating Bridge | B19: 5789.17 | C19: 642601.96 | D19: K$ | E19: =B19/C19 -> 0.0090089517 | H19: Transportation, Bridges | I19: Seattle, WA | J19: USA
A20: Project Neon | B20: 5539.52 | C20: 611670.06 | D20: K$ | E20: =B20/C20 -> 0.0090563857 | F20: Yes | G20: =IF(F20="Yes",E20,"") -> 0.0090563857 | H20: Transportation, Highway | I20: Las Vegas, NV | J20: USA
A21: Mountain View Corridor | B21: 2199.24 | C21: 229878.6 | D21: K$ | E21: =B21/C21 -> 0.0095669627 | F21: Yes | G21: =IF(F21="Yes",E21,"") -> 0.0095669627 | H21: Transportation, Highway | I21: Salt Lake City, UT | J21: USA
A22: E-360 Bellevue to Redmond | B22: 2290.37 | C22: 236570.04 | D22: K$ | E22: =B22/C22 -> 0.0096815725 | F22: Yes | G22: =IF(F22="Yes",E22,"") -> 0.0096815725 | H22: Transportation, Highway | I22: Seattle, WA | J22: USA
A23: Arlington Memorial Bridge | B23: 1558.28 | C23: 159839.66 | D23: K$ | E23: =B23/C23 -> 0.0097490197 | H23: Transportation, Bridges | I23: Arlington, VA | J23: USA
A24: I-17 Anthem | B24: 3210.57 | C24: 320071.89 | D24: K$ | E24: =B24/C24 -> 0.010030778 | F24: Yes | G24: =IF(F24="Yes",E24,"") -> 0.010030778 | H24: Transportation, Highway | I24: Phoenix, AZ | J24: USA
A25: Anthony Henday-Stony Plain | B25: 1905.94 | C25: 187397.98 | D25: K$ | E25: =B25/C25 -> 0.010170547 | F25: Yes | G25: =IF(F25="Yes",E25,"") -> 0.010170547 | H25: Transportation, Highway | I25: Edmonton, AB | J25: CAN
A26: SH-183 Midtown Express | B26: 9424.17 | C26: 885258.97 | D26: K$ | E26: =B26/C26 -> 0.010645665 | F26: Yes | G26: =IF(F26="Yes",E26,"") -> 0.010645665 | H26: Transportation, Highway | I26: Dallas, TX | J26: USA
A27: ICC-B | B27: 5009.29 | C27: 454376.58 | D27: K$ | E27: =B27/C27 -> 0.011024534 | F27: Yes | G27: =IF(F27="Yes",E27,"") -> 0.011024534 | H27: Transportation, Highway | I27: Silver Springs, MD | J27: USA
A28: Pioneer Crossing | B28: 2102.32 | C28: 177230.46 | D28: K$ | E28: =B28/C28 -> 0.011862069 | F28: Yes | G28: =IF(F28="Yes",E28,"") -> 0.011862069 | H28: Transportation, Highway | I28: Saratoga Springs, UT | J28: USA
A29: I-225 | B29: 5263.24 | C29: 424701.71 | D29: K$ | E29: =B29/C29 -> 0.012392792 | F29: Yes | G29: =IF(F29="Yes",E29,"") -> 0.012392792 | H29: Transportation, Highway | I29: Denver, CO | J29: USA
A30: Farrington Guideway | B30: 8764.95 | C30: 684456.77 | D30: K$ | E30: =B30/C30 -> 0.012805703 | H30: Transit, Light Rail | I30: Oahu, HI | J30: USA
A31: I-405 Renton to Bellevue | B31: 8305.85 | C31: 615922 | D31: K$ | E31: =B31/C31 -> 0.01348523 | F31: Yes | G31: =IF(F31="Yes",E31,"") -> 0.01348523 | H31: Transportation, Highway | I31: Bellevue, WA | J31: USA
A32: Northwest Parkway | B32: 2059.46 | C32: 152435.75 | D32: K$ | E32: =B32/C32 -> 0.013510348 | F32: Yes | G32: =IF(F32="Yes",E32,"") -> 0.013510348 | H32: Transportation, Highway | I32: Denver, CO | J32: USA
A33: I-15 Tropicana | B33: 4650.13 | C33: 328887.12 | D33: K$ | E33: =B33/C33 -> 0.014138985 | F33: Yes | G33: =IF(F33="Yes",E33,"") -> 0.014138985 | H33: Transportation, Highway | I33: Las Vegas, NV | J33: USA
A34: Kamehameha Guideway | B34: 6071.66 | C34: 428252.13 | D34: K$ | E34: =B34/C34 -> 0.01417777 | H34: Transit, Light Rail | I34: Honolulu, HI | J34: USA
A35: Turcot | B35: 24752.38 | C35: 1703515.5 | D35: K$ | E35: =B35/C35 -> 0.014530176 | F35: Yes | G35: =IF(F35="Yes",E35,"") -> 0.014530176 | H35: Transportation, Highway | I35: Montreal, QC | J35: CAN
A36: Selmon Expressway Extension | B36: 4154.99 | C36: 253154.83 | D36: K$ | E36: =B36/C36 -> 0.016412841 | F36: Yes | G36: =IF(F36="Yes",E36,"") -> 0.016412841 | H36: Transportation, Highway | I36: Tampa, FL | J36: USA
A37: Southwest Calgary Ring Road | B37: 23281.64 | C37: 1325890.7 | D37: K$ | E37: =B37/C37 -> 0.017559246 | F37: Yes | G37: =IF(F37="Yes",E37,"") -> 0.017559246 | H37: Transportation, Highway | I37: Calgary, AB | J37: USA
A38: A-25 Bridge and Highway | B38: 7407.17 | C38: 420771.29 | D38: K$ | E38: =B38/C38 -> 0.017603791 | H38: Transportation, Bridges | I38: Laval, QC | J38: CAN
A39: BART Warm Springs | B39: 7824.31 | C39: 428566.69 | D39: K$ | E39: =B39/C39 -> 0.018256925 | H39: Transit, Light Rail | I39: Oakland, CA | J39: USA
A40: Sea-to-Sky Highway | B40: 3379.41 | C40: 590638.34 | D40: K$ | E40: =B40/C40 -> 0.0057216232 | F40: Yes | G40: =IF(F40="Yes",E40,"") -> 0.0057216232 | H40: Transportation, Highway | I40: Vancoucer, BC | J40: CAN
A41: WMATA Yellow / Blue Lines | B41: 991.97 | C41: 191891.46 | D41: K$ | E41: =B41/C41 -> 0.0051694328 | H41: Transit, Light Rail | I41: Alexandria, VA | J41: USA
...

Sheet TSCD
A1: Temporary Structures & Construction Devices (TSCD)
A2: eQTY: Anticipated Project Cost
A4: Project | B4: ESDC Cost | C4: eQTY | D4: Unit | E4: Production | F4: Applicable Job | G4: Custom | H4: Market | I4: City, State | J4: Country
A5: IH 820 Southeast Connector | B5: 7812.04 | C5: 2006033 | D5: K$ | E5: =B5/C5 -> 0.0038942729 | F5: Yes | G5: =IF(F5="Yes",E5,"") -> 0.0038942729 | H5: Transportation, Highway | I5: Fort Worth, TX | J5: USA
A6: E-130 LRT | B6: 1955.98 | C6: 820594.77 | D6: K$ | E6: =B6/C6 -> 0.0023836126 | H6: Transit, Light Rail | I6: Seattle, WA | J6: USA
A7: Connect 4 | B7: 1491.45 | C7: 268033.92 | D7: K$ | E7: =B7/C7 -> 0.0055644077 | F7: Yes | G7: =IF(F7="Yes",E7,"") -> 0.0055644077 | H7: Transportation, Highway | I7: Fort Worth, TX | J7: USA
A8: Foothill Phase 2B1 LRT | B8: 809.18 | C8: 836559.23 | D8: K$ | E8: =B8/C8 -> 0.00096727162 | H8: Transit, Light Rail | I8: San Dimas, CA | J8: USA
A9: I-15 Tropicana | B9: 830.59 | C9: 368187.07 | D9: K$ | E9: =B9/C9 -> 0.0022558913 | F9: Yes | G9: =IF(F9="Yes",E9,"") -> 0.0022558913 | H9: Transportation, Highway | I9: Las Vegas, NV | J9: USA
A10: C-70 | B10: 7441.71 | C10: 1290640.7 | D10: K$ | E10: =B10/C10 -> 0.0057659038 | F10: Yes | G10: =IF(F10="Yes",E10,"") -> 0.0057659038 | H10: Transportation, Highway | I10: Denver, CO | J10: USA
A11: Turcot | B11: 9542.25 | C11: 1784779.8 | D11: K$ | E11: =B11/C11 -> 0.0053464579 | F11: Yes | G11: =IF(F11="Yes",E11,"") -> 0.0053464579 | H11: Transportation, Highway | I11: Montreal, QB | J11: CAN
A12: Federal Way Link Extension | B12: 1889.68 | C12: 1403683.5 | D12: K$ | E12: =B12/C12 -> 0.0013462294 | H12: Transit, Light Rail | I12: Federal Way, WA | J12: USA
A13: Southwest Calgary Ring Road | B13: 2905.56 | C13: 1310255.1 | D13: K$ | E13: =B13/C13 -> 0.0022175529 | F13: Yes | G13: =IF(F13="Yes",E13,"") -> 0.0022175529 | H13: Transportation, Highway | I13: Calgary, AB | J13: CAN
A14: Goethals Bridge Replacement | B14: 1935.06 | C14: 1091231.6 | D14: K$ | E14: =B14/C14 -> 0.0017732808 | F14: Yes | G14: =IF(F14="Yes",E14,"") -> 0.0017732808 | H14: Transportation, Bridges | I14: Staten Island, NY | J14: USA
A15: Midtown Express | B15: 1552.51 | C15: 914940.51 | D15: K$ | E15: =B15/C15 -> 0.0016968426 | F15: Yes | G15: =IF(F15="Yes",E15,"") -> 0.0016968426 | H15: Transportation, Highway | I15: Irving, TX | J15: USA
A16: South Central LRT Extension | B16: 592.66 | C16: 823932.77 | D16: K$ | E16: =B16/C16 -> 0.00071930626 | H16: Transit, Light Rail | I16: Phoenix, AZ | J16: USA
A17: Border West Expressway | B17: 1858.64 | C17: 691683.83 | D17: K$ | E17: =B17/C17 -> 0.0026871237 | F17: Yes | G17: =IF(F17="Yes",E17,"") -> 0.0026871237 | H17: Transportation, Highway | I17: El Paso, TX | J17: USA
A18: Project Neon | B18: 931.75 | C18: 628296.99 | D18: K$ | E18: =B18/C18 -> 0.001482977 | F18: Yes | G18: =IF(F18="Yes",E18,"") -> 0.001482977 | H18: Transportation, Highway | I18: Las Vegas, NV | J18: USA
A19: 30 Crossing | B19: 1551.47 | C19: 497061.58 | D19: K$ | E19: =B19/C19 -> 0.0031212833 | F19: Yes | G19: =IF(F19="Yes",E19,"") -> 0.0031212833 | H19: Transportation, Bridges | I19: Little Rock, AR | J19: USA
A20: I-225 Light Rail Corridor | B20: 649.55 | C20: 427748.52 | D20: K$ | E20: =B20/C20 -> 0.0015185324 | H20: Transit, Light Rail | I20: Aurora, CO | J20: USA
A21: E-360 Bellevue to Redmond | B21: 540.12 | C21: 270974.68 | D21: K$ | E21: =B21/C21 -> 0.001993249 | H21: Transit, Light Rail | I21: Redmond, WA | J21: USA
A22: Selmon Expresseway Extension | B22: 1955.92 | C22: 262650 | D22: K$ | E22: =B22/C22 -> 0.0074468685 | F22: Yes | G22: =IF(F22="Yes",E22,"") -> 0.0074468685 | H22: Transportation, Highway | I22: Tampa, FL | J22: USA
A23: Flyway 470 | B23: 898.39 | C23: 256515.18 | D23: K$ | E23: =B23/C23 -> 0.0035022879 | F23: Yes | G23: =IF(F23="Yes",E23,"") -> 0.0035022879 | H23: Transportation, Highway | I23: Aurora, CO | J23: USA
A24: WMATA Station Rehab Contract 3 | B24: 548.39 | C24: 253581.12 | D24: K$ | E24: =B24/C24 -> 0.0021625821 | H24: Transit, Light Rail | I24: Greenbelt, WA | J24: USA
A25: WMATA Station Rehab Contract 4 | B25: 846.77 | C25: 252986.82 | D25: K$ | E25: =B25/C25 -> 0.0033470914 | H25: Transit, Light Rail | I25: Hyattsville, WA | J25: USA
A26: MVC 4100 South to SR-201 | B26: 131.57 | C26: 229983.74 | D26: K$ | E26: =B26/C26 -> 0.00057208392 | F26: Yes | G26: =IF(F26="Yes",E26,"") -> 0.00057208392 | H26: Transportation, Highway | I26: West Valley City, UT | J26: USA
A27: Northwest Phase 2 LRT Extension | B27: 181.77 | C27: 214449.31 | D27: K$ | E27: =B27/C27 -> 0.00084761289 | H27: Transit, Light Rail | I27: Phoenix, AZ | J27: USA
A28: Tlicho All-Season Road | B28: 216.41 | C28: 183706.28 | D28: K$ | E28: =B28/C28 -> 0.0011780218 | F28: Yes | G28: =IF(F28="Yes",E28,"") -> 0.0011780218 | H28: Transportation, Highway | I28: Whati, ON | J28: USA
A29: WMATA Orange / Silver Line | B29: 464.64 | C29: 178931.16 | D29: K$ | E29: =B29/C29 -> 0.0025967529 | H29: Transit, Light Rail | I29: Arlington, VA | J29: USA
A30: WMATA Yellow Line Rehab | B30: 920.05 | C30: 175655.73 | D30: K$ | E30: =B30/C30 -> 0.0052378024 | H30: Transit, Light Rail | I30: Washington, DC | J30: USA
A31: I-10 Capital Corridor | B31: 1776.12 | C31: 159847.91 | D31: K$ | E31: =B31/C31 -> 0.011111312 | F31: Yes | G31: =IF(F31="Yes",E31,"") -> 0.011111312 | H31: Transportation, Highway | I31: Baton Rouge, LA | J31: USA
A32: Nashville Connector | B32: 361.46 | C32: 148878.92 | D32: K$ | E32: =B32/C32 -> 0.002427879 | F32: Yes | G32: =IF(F32="Yes",E32,"") -> 0.002427879 | H32: Transportation, Bridges | I32: Nashville, TN | J32: USA
A33: Moosejaw | B33: 759.58 | C33: 148722.83 | D33: K$ | E33: =B33/C33 -> 0.0051073531 | F33: Yes | G33: =IF(F33="Yes",E33,"") -> 0.0051073531 | H33: Transporation, Highway | I33: Virginia, MT | J33: USA
A34: Big Thompson | B34: 235.58 | C34: 146038.94 | D34: K$ | E34: =B34/C34 -> 0.0016131314 | F34: Yes | G34: =IF(F34="Yes",E34,"") -> 0.0016131314 | H34: Transportation, Highway | I34: Loveland, CO | J34: USA
A35: Kingston Third Crossing | B35: 1140.54 | C35: 144336.5 | D35: K$ | E35: =B35/C35 -> 0.0079019513 | F35: Yes | G35: =IF(F35="Yes",E35,"") -> 0.0079019513 | H35: Transportation, Bridges | I35: Kingston, ON | J35: USA
A36: Porter Road | B36: 770.65 | C36: 112340.79 | D36: K$ | E36: =B36/C36 -> 0.0068599304 | F36: Yes | G36: =IF(F36="Yes",E36,"") -> 0.0068599304 | H36: Transportation, Highway | I36: Springdale, TX | J36: USA
A37: SR 99 Alaskan Way Viaduct Demo | B37: 1101.92 | C37: 98750.74 | D37: K$ | E37: =B37/C37 -> 0.0111586 | H37: Transportation, Bridges | I37: Seattle, WA | J37: USA
A38: LA 1: Port Allen Canal Bridge | B38: 104.12 | C38: 96311.72 | D38: K$ | E38: =B38/C38 -> 0.001081073 | H38: Transportation, Bridges | I38: Port Allen, LA | J38: USA
A39: CTA Congress Track Phase 1 | B39: 65.34 | C39: 89697.94 | D39: K$ | E39: =B39/C39 -> 0.00072844482 | H39: Transit, Light Rail | I39: Chicago, IL | J39: USA
A40: Fort Smith | B40: 313.47 | C40: 82226.01 | D40: K$ | E40: =B40/C40 -> 0.0038122973 | H40: Transportation, Highway | I40: Fort Smith, TX | J40: USA
A41: I-40 Gorge Bridge #171 | B41: 238.23 | C41: 81544.24 | D41: K$ | E41: =B41/C41 -> 0.0029214816 | H41: Transportation, Bridges | I41: Asheville, NC | J41: USA
...

Sheet Notes
A43: Trendline Equations:
A44: https://www.ablebits.com/office-addins-blog/excel-trendline-types-equations-formulas/#logarithmic-trendline

Sheet Dropdowns
A1: Digital Engineering: Complexity
A2: Low
A3: Low-Med
A4: Med
A5: Med-High
A6: High
A8: Allowable Multiplier | B8: 2.85
A9: Hourly Composite Rate | B9: 64.5
